Workbook

Sheet Reporting Categories
A1: Personal Budget – Reporting Categories
A3: # | B3: Category | C3: Type | D3: Description / Examples | E3: Plaid Mapping
A4: 1 | B4: Income | C4: Income | D4: Paycheck, transfers in, refunds, interest (positive) | E4: Income; Transfer > Payroll; Interest (positive)
A5: 2 | B5: Housing | C5: Expense | D5: Rent, mortgage, property tax, home insurance | E5: Payment > Rent
A6: 3 | B6: Bills & Utilities | C6: Expense | D6: Phone, internet, electric, water, gas, insurance premiums | E6: Utilities; Payment > *; Tax
A7: 4 | B7: Groceries | C7: Expense | D7: Supermarkets, grocery stores, wholesale clubs | E7: Food and Drink > Groceries; Shops > Supermarkets
A8: 5 | B8: Dining Out | C8: Expense | D8: Restaurants, fast food, coffee shops, bars, delivery | E8: Food and Drink > Restaurants; Food and Drink > *
A9: 6 | B9: Transportation | C9: Expense | D9: Gas, parking, public transit, rideshare, car maintenance | E9: Travel > * (non-airline/lodging)
A10: 7 | B10: Shopping | C10: Expense | D10: Retail, Amazon, clothing, electronics, general merchandise | E10: Shops > * (non-supermarket)
A11: 8 | B11: Entertainment | C11: Expense | D11: Streaming services, movies, games, concerts, events | E11: Recreation
A12: 9 | B12: Health | C12: Expense | D12: Pharmacy, doctor visits, gym memberships, medical bills | E12: Healthcare
A13: 10 | B13: Travel | C13: Expense | D13: Flights, hotels, vacation rentals, travel booking | E13: Travel > Airlines; Travel > Lodging
A14: 11 | B14: Subscriptions | C14: Expense | D14: Recurring services (SaaS, news, apps, memberships) | E14: Service > Subscription
A15: 12 | B15: Personal Care | C15: Expense | D15: Haircuts, beauty, spa, cosmetics | E15: Service > Personal Care
... A20: 17 | B20: Other / Uncategorized | C20: Expense | D20: Anything that doesn't fit above; fallback category | E20: Cash Advance; Community; Service > *

Sheet Plaid Category Mapping
A1: Plaid Category → App Category Mapping
A3: Plaid Category (Primary > Secondary) | B3: App Category | C3: Notes
A4: Income | B4: Income | C4: Direct mapping
A5: Transfer > Payroll | B5: Income | C5: Payroll deposits
A6: Interest (positive) | B6: Income | C6: Savings interest, dividends
A7: Bank Fees | B7: Fees & Charges | C7: All bank fee types
A8: Interest (negative) | B8: Fees & Charges | C8: Interest charges on credit
A9: Cash Advance | B9: Other | C9: Rare; flag for review
A10: Community | B10: Other | C10: Community-related services
A11: Food and Drink > Restaurants | B11: Dining Out | C11: Includes fast food, cafes
A12: Food and Drink > Groceries | B12: Groceries | C12: Grocery-specific merchants
A13: Food and Drink > Coffee Shop | B13: Dining Out | C13: Starbucks, etc.
A14: Food and Drink > * | B14: Dining Out | C14: Catch-all food & drink
... A40: Utilities | B40: Bills & Utilities | C40: Electric, water, gas

Sheet Monthly Budget
A1: Monthly Budget – 12-Month Plan
A3: Category | B3: Jan | C3: Feb | D3: Mar | E3: Apr | F3: May | G3: Jun | H3: Jul | I3: Aug | J3: Sep | K3: Oct | L3: Nov | M3: Dec | N3: Annual Total
A4: INCOME
A5: Salary / Paycheck | B5: 0 | C5: 0 | D5: 0 | E5: 0 | F5: 0 | G5: 0 | H5: 0 | I5: 0 | J5: 0 | K5: 0 | L5: 0 | M5: 0 | N5: =SUM(B5:M5)
A6: Side Income | B6: 0 | C6: 0 | D6: 0 | E6: 0 | F6: 0 | G6: 0 | H6: 0 | I6: 0 | J6: 0 | K6: 0 | L6: 0 | M6: 0 | N6: =SUM(B6:M6)
A7: Interest / Dividends | B7: 0 | C7: 0 | D7: 0 | E7: 0 | F7: 0 | G7: 0 | H7: 0 | I7: 0 | J7: 0 | K7: 0 | L7: 0 | M7: 0 | N7: =SUM(B7:M7)
A8: Refunds | B8: 0 | C8: 0 | D8: 0 | E8: 0 | F8: 0 | G8: 0 | H8: 0 | I8: 0 | J8: 0 | K8: 0 | L8: 0 | M8: 0 | N8: =SUM(B8:M8)
A9: Other Income | B9: 0 | C9: 0 | D9: 0 | E9: 0 | F9: 0 | G9: 0 | H9: 0 | I9: 0 | J9: 0 | K9: 0 | L9: 0 | M9: 0 | N9: =SUM(B9:M9)
A10: TOTAL INCOME | B10: =SUM(B5:B9) | C10: =SUM(C5:C9) | D10: =SUM(D5:D9) | E10: =SUM(E5:E9) | F10: =SUM(F5:F9) | G10: =SUM(G5:G9) | H10: =SUM(H5:H9) | I10: =SUM(I5:I9) | ... N10: =SUM(N5:N9)
A12: EXPENSES
A13: Housing | B13: =SUM(B14:B18) | C13: =SUM(C14:C18) | D13: =SUM(D14:D18) | E13: =SUM(E14:E18) | F13: =SUM(F14:F18) | G13: =SUM(G14:G18) | H13: =SUM(H14:H18) | I13: =SUM(I14:I18) | ... N13: =SUM(N14:N18)
A14: Rent / Mortgage | B14: 0 | C14: 0 | D14: 0 | E14: 0 | F14: 0 | G14: 0 | H14: 0 | I14: 0 | J14: 0 | K14: 0 | L14: 0 | M14: 0 | N14: =SUM(B14:M14)
A15: Property Tax | B15: 0 | C15: 0 | D15: 0 | E15: 0 | F15: 0 | G15: 0 | H15: 0 | I15: 0 | J15: 0 | K15: 0 | L15: 0 | M15: 0 | N15: =SUM(B15:M15)
A16: Home Insurance | B16: 0 | C16: 0 | D16: 0 | E16: 0 | F16: 0 | G16: 0 | H16: 0 | I16: 0 | J16: 0 | K16: 0 | L16: 0 | M16: 0 | N16: =SUM(B16:M16)
A17: HOA Fees | B17: 0 | C17: 0 | D17: 0 | E17: 0 | F17: 0 | G17: 0 | H17: 0 | I17: 0 | J17: 0 | K17: 0 | L17: 0 | M17: 0 | N17: =SUM(B17:M17)
A18: Home Maintenance | B18: 0 | C18: 0 | D18: 0 | E18: 0 | F18: 0 | G18: 0 | H18: 0 | I18: 0 | J18: 0 | K18: 0 | L18: 0 | M18: 0 | N18: =SUM(B18:M18)
A19: Bills & Utilities | B19: =SUM(B20:B25) | C19: =SUM(C20:C25) | D19: =SUM(D20:D25) | E19: =SUM(E20:E25) | F19: =SUM(F20:F25) | G19: =SUM(G20:G25) | H19: =SUM(H20:H25) | I19: =SUM(I20:I25) | ... N19: =SUM(N20:N25)
A20: Electric | B20: 0 | C20: 0 | D20: 0 | E20: 0 | F20: 0 | G20: 0 | H20: 0 | I20: 0 | J20: 0 | K20: 0 | L20: 0 | M20: 0 | N20: =SUM(B20:M20)
A21: Water / Sewer | B21: 0 | C21: 0 | D21: 0 | E21: 0 | F21: 0 | G21: 0 | H21: 0 | I21: 0 | J21: 0 | K21: 0 | L21: 0 | M21: 0 | N21: =SUM(B21:M21)
A22: Gas (home) | B22: 0 | C22: 0 | D22: 0 | E22: 0 | F22: 0 | G22: 0 | H22: 0 | I22: 0 | J22: 0 | K22: 0 | L22: 0 | M22: 0 | N22: =SUM(B22:M22)
A23: Internet | B23: 0 | C23: 0 | D23: 0 | E23: 0 | F23: 0 | G23: 0 | H23: 0 | I23: 0 | J23: 0 | K23: 0 | L23: 0 | M23: 0 | N23: =SUM(B23:M23)
A24: Phone | B24: 0 | C24: 0 | D24: 0 | E24: 0 | F24: 0 | G24: 0 | H24: 0 | I24: 0 | J24: 0 | K24: 0 | L24: 0 | M24: 0 | N24: =SUM(B24:M24)
A25: Insurance (auto/health/life) | B25: 0 | C25: 0 | D25: 0 | E25: 0 | F25: 0 | G25: 0 | H25: 0 | I25: 0 | J25: 0 | K25: 0 | L25: 0 | M25: 0 | N25: =SUM(B25:M25)
A26: Groceries | B26: =SUM(B27:B28) | C26: =SUM(C27:C28) | D26: =SUM(D27:D28) | E26: =SUM(E27:E28) | F26: =SUM(F27:F28) | G26: =SUM(G27:G28) | H26: =SUM(H27:H28) | I26: =SUM(I27:I28) | ... N26: =SUM(N27:N28)
A27: Grocery Stores | B27: 0 | C27: 0 | D27: 0 | E27: 0 | F27: 0 | G27: 0 | H27: 0 | I27: 0 | J27: 0 | K27: 0 | L27: 0 | M27: 0 | N27: =SUM(B27:M27)
A28: Wholesale Clubs (Costco, etc.) | B28: 0 | C28: 0 | D28: 0 | E28: 0 | F28: 0 | G28: 0 | H28: 0 | I28: 0 | J28: 0 | K28: 0 | L28: 0 | M28: 0 | N28: =SUM(B28:M28)
A29: Dining Out | B29: =SUM(B30:B33) | C29: =SUM(C30:C33) | D29: =SUM(D30:D33) | E29: =SUM(E30:E33) | F29: =SUM(F30:F33) | G29: =SUM(G30:G33) | H29: =SUM(H30:H33) | I29: =SUM(I30:I33) | ... N29: =SUM(N30:N33)
A30: Restaurants | B30: 0 | C30: 0 | D30: 0 | E30: 0 | F30: 0 | G30: 0 | H30: 0 | I30: 0 | J30: 0 | K30: 0 | L30: 0 | M30: 0 | N30: =SUM(B30:M30)
A31: Fast Food | B31: 0 | C31: 0 | D31: 0 | E31: 0 | F31: 0 | G31: 0 | H31: 0 | I31: 0 | J31: 0 | K31: 0 | L31: 0 | M31: 0 | N31: =SUM(B31:M31)
A32: Coffee Shops | B32: 0 | C32: 0 | D32: 0 | E32: 0 | F32: 0 | G32: 0 | H32: 0 | I32: 0 | J32: 0 | K32: 0 | L32: 0 | M32: 0 | N32: =SUM(B32:M32)
A33: Food Delivery | B33: 0 | C33: 0 | D33: 0 | E33: 0 | F33: 0 | G33: 0 | H33: 0 | I33: 0 | J33: 0 | K33: 0 | L33: 0 | M33: 0 | N33: =SUM(B33:M33)
A34: Transportation | B34: =SUM(B35:B41) | C34: =SUM(C35:C41) | D34: =SUM(D35:D41) | E34: =SUM(E35:E41) | F34: =SUM(F35:F41) | G34: =SUM(G35:G41) | H34: =SUM(H35:H41) | I34: =SUM(I35:I41) | ... N34: =SUM(N35:N41)
A35: Gas (auto) | B35: 0 | C35: 0 | D35: 0 | E35: 0 | F35: 0 | G35: 0 | H35: 0 | I35: 0 | J35: 0 | K35: 0 | L35: 0 | M35: 0 | N35: =SUM(B35:M35)
A36: Car Payment | B36: 0 | C36: 0 | D36: 0 | E36: 0 | F36: 0 | G36: 0 | H36: 0 | I36: 0 | J36: 0 | K36: 0 | L36: 0 | M36: 0 | N36: =SUM(B36:M36)
A37: Car Insurance | B37: 0 | C37: 0 | D37: 0 | E37: 0 | F37: 0 | G37: 0 | H37: 0 | I37: 0 | J37: 0 | K37: 0 | L37: 0 | M37: 0 | N37: =SUM(B37:M37)
A38: Parking | B38: 0 | C38: 0 | D38: 0 | E38: 0 | F38: 0 | G38: 0 | H38: 0 | I38: 0 | J38: 0 | K38: 0 | L38: 0 | M38: 0 | N38: =SUM(B38:M38)
A39: Public Transit | B39: 0 | C39: 0 | D39: 0 | E39: 0 | F39: 0 | G39: 0 | H39: 0 | I39: 0 | J39: 0 | K39: 0 | L39: 0 | M39: 0 | N39: =SUM(B39:M39)
A40: Rideshare (Uber/Lyft) | B40: 0 | C40: 0 | D40: 0 | E40: 0 | F40: 0 | G40: 0 | H40: 0 | I40: 0 | J40: 0 | K40: 0 | L40: 0 | M40: 0 | N40: =SUM(B40:M40)
A41: Car Maintenance | B41: 0 | C41: 0 | D41: 0 | E41: 0 | F41: 0 | G41: 0 | H41: 0 | I41: 0 | J41: 0 | K41: 0 | L41: 0 | M41: 0 | N41: =SUM(B41:M41)
A42: Shopping | B42: =SUM(B43:B47) | C42: =SUM(C43:C47) | D42: =SUM(D43:D47) | E42: =SUM(E43:E47) | F42: =SUM(F43:F47) | G42: =SUM(G43:G47) | H42: =SUM(H43:H47) | I42: =SUM(I43:I47) | ... N42: =SUM(N43:N47)
...

Sheet Dashboard
A1: Budget Dashboard – Monthly Summary
A3: This dashboard references the 'Monthly Budget' sheet. Enter your data there and this will update automatically.
A5: Total Annual Income | D5: Total Annual Expenses | G5: Annual Net Cash Flow
A6: ='Monthly Budget'!N10 | D6: ='Monthly Budget'!N81 | G6: ='Monthly Budget'!N83
A9: Metric | B9: Jan | C9: Feb | D9: Mar | E9: Apr | F9: May | G9: Jun | H9: Jul | I9: Aug | J9: Sep | K9: Oct | L9: Nov | M9: Dec
A10: Total Income | B10: ='Monthly Budget'!B10 | C10: ='Monthly Budget'!C10 | D10: ='Monthly Budget'!D10 | E10: ='Monthly Budget'!E10 | F10: ='Monthly Budget'!F10 | G10: ='Monthly Budget'!G10 | H10: ='Monthly Budget'!H10 | I10: ='Monthly Budget'!I10 | ... M10: ='Monthly Budget'!M10
A11: Total Expenses | B11: ='Monthly Budget'!B81 | C11: ='Monthly Budget'!C81 | D11: ='Monthly Budget'!D81 | E11: ='Monthly Budget'!E81 | F11: ='Monthly Budget'!F81 | G11: ='Monthly Budget'!G81 | H11: ='Monthly Budget'!H81 | I11: ='Monthly Budget'!I81 | ... M11: ='Monthly Budget'!M81
A12: Net Cash Flow | B12: ='Monthly Budget'!B83 | C12: ='Monthly Budget'!C83 | D12: ='Monthly Budget'!D83 | E12: ='Monthly Budget'!E83 | F12: ='Monthly Budget'!F83 | G12: ='Monthly Budget'!G83 | H12: ='Monthly Budget'!H83 | I12: ='Monthly Budget'!I83 | ... M12: ='Monthly Budget'!M83

Sheet Budget vs Actual
A1: Budget vs Actual – Monthly Comparison
A3: Select Month: | B3: January
A5: Category | B5: Budget | C5: Actual | D5: Variance ($) | E5: Variance (%) | F5: Status
A6: Housing | B6: 0 | C6: 0 | D6: =B6-C6 | E6: =IFERROR((B6-C6)/B6,0) | F6: =IF(C6<=B6,"Under Budget","Over Budget")
A7: Bills & Utilities | B7: 0 | C7: 0 | D7: =B7-C7 | E7: =IFERROR((B7-C7)/B7,0) | F7: =IF(C7<=B7,"Under Budget","Over Budget")
A8: Groceries | B8: 0 | C8: 0 | D8: =B8-C8 | E8: =IFERROR((B8-C8)/B8,0) | F8: =IF(C8<=B8,"Under Budget","Over Budget")
A9: Dining Out | B9: 0 | C9: 0 | D9: =B9-C9 | E9: =IFERROR((B9-C9)/B9,0) | F9: =IF(C9<=B9,"Under Budget","Over Budget")
A10: Transportation | B10: 0 | C10: 0 | D10: =B10-C10 | E10: =IFERROR((B10-C10)/B10,0) | F10: =IF(C10<=B10,"Under Budget","Over Budget")
A11: Shopping | B11: 0 | C11: 0 | D11: =B11-C11 | E11: =IFERROR((B11-C11)/B11,0) | F11: =IF(C11<=B11,"Under Budget","Over Budget")
A12: Entertainment | B12: 0 | C12: 0 | D12: =B12-C12 | E12: =IFERROR((B12-C12)/B12,0) | F12: =IF(C12<=B12,"Under Budget","Over Budget")
A13: Health | B13: 0 | C13: 0 | D13: =B13-C13 | E13: =IFERROR((B13-C13)/B13,0) | F13: =IF(C13<=B13,"Under Budget","Over Budget")
A14: Travel | B14: 0 | C14: 0 | D14: =B14-C14 | E14: =IFERROR((B14-C14)/B14,0) | F14: =IF(C14<=B14,"Under Budget","Over Budget")
A15: Subscriptions | B15: 0 | C15: 0 | D15: =B15-C15 | E15: =IFERROR((B15-C15)/B15,0) | F15: =IF(C15<=B15,"Under Budget","Over Budget")
A16: Personal Care | B16: 0 | C16: 0 | D16: =B16-C16 | E16: =IFERROR((B16-C16)/B16,0) | F16: =IF(C16<=B16,"Under Budget","Over Budget")
A17: Education | B17: 0 | C17: 0 | D17: =B17-C17 | E17: =IFERROR((B17-C17)/B17,0) | F17: =IF(C17<=B17,"Under Budget","Over Budget")
... A20: Other / Uncategorized | B20: 0 | C20: 0 | D20: =B20-C20 | E20: =IFERROR((B20-C20)/B20,0) | F20: =IF(C20<=B20,"Under Budget","Over Budget")
A21: TOTAL | B21: =SUM(B6:B20) | C21: =SUM(C6:C20) | D21: =SUM(D6:D20) | E21: =IFERROR((B21-C21)/B21,0) | F21: =IF(C21<=B21,"Under Budget","Over Budget")

Sheet Transaction Log
A1: Transaction Log – Raw Transaction Data
A3: Date | B3: Merchant / Description | C3: Amount | D3: Plaid Category | E3: App Category | F3: Account | G3: Pending | H3: Notes
A4: 2026-01-15 | B4: Whole Foods Market | C4: 87.32 | D4: Food and Drink > Groceries | E4: Groceries | F4: Checking ****1234 | G4: No
A5: 2026-01-15 | B5: Uber Eats | C5: 32.5 | D5: Food and Drink > Restaurants > Fast Food | E5: Dining Out | F5: Credit Card ****5678 | G5: No
A6: 2026-01-14 | B6: Shell Gas Station | C6: 45 | D6: Travel > Gas | E6: Transportation | F6: Credit Card ****5678 | G6: No
A7: 2026-01-14 | B7: Netflix | C7: 15.99 | D7: Service > Subscription | E7: Subscriptions | F7: Credit Card ****5678 | G7: No | H7: Monthly
A8: 2026-01-13 | B8: Target | C8: 124.56 | D8: Shops > General Merchandise | E8: Shopping | F8: Credit Card ****5678 | G8: Yes | H8: Pending
A9: 2026-01-13 | B9: Employer Direct Deposit | C9: -3500 | D9: Transfer > Payroll | E9: Income | F9: Checking ****1234 | G9: No | H9: Bi-weekly pay
A10: 2026-01-12 | B10: Walgreens Pharmacy | C10: 22.45 | D10: Healthcare > Pharmacy | E10: Health | F10: Credit Card ****5678 | G10: No
A11: 2026-01-12 | B11: Spotify | C11: 9.99 | D11: Service > Subscription | E11: Subscriptions | F11: Credit Card ****5678 | G11: No | H11: Monthly
A12: 2026-01-11 | B12: Rent Payment | C12: 1800 | D12: Payment > Rent | E12: Housing | F12: Checking ****1234 | G12: No | H12: Monthly rent
A13: 2026-01-10 | B13: Venmo Transfer | C13: 50 | D13: Transfer > Third Party | E13: Transfer | F13: Checking ****1234 | G13: No | H13: Split dinner

Sheet Assumptions & Notes
A1: Model Assumptions & Notes
A3: Topic | B3: Assumption | C3: Notes
A4: Data Source | B4: Plaid API (Sandbox mode for Phase 1) | C4: Production Plaid requires OAuth approval
A5: Category System | B5: 17 categories mapped from Plaid's 3-level hierarchy | C5: User overrides take priority over Plaid auto-categorization
A6: Transfer Handling | B6: Transfers excluded from income/expense totals | C6: Categorized separately to avoid double-counting
A7: Pending Transactions | B7: Included in log with 'Pending' flag | C7: Will update on next Plaid sync
A8: Income Recognition | B8: Income = negative amounts in Plaid (money flowing in) | C8: Payroll, refunds, interest (positive)
A9: Expense Recognition | B9: Expenses = positive amounts in Plaid (money flowing out) | C9: All spending categories
A10: Currency | B10: USD only for Phase 1 | C10: Multi-currency support out of scope
A11: Time Period | B11: Monthly reporting periods | C11: Calendar month boundaries
A12: Budget Method | B12: Zero-based budgeting approach | C12: Every dollar assigned a category
A13: Savings Rate | B13: =Net Cash Flow / Total Income | C13: Target: 20%+ for healthy finances
